Traceback (most recent call last):
  File "./add_members_to_group.py", line 109, in <module>
    client(InviteToChannelRequest(target_group_entity,[user_to_add]))
  File "/usr/local/lib/python3.6/dist-packages/telethon/sync.py", line 39, in syncified
    return loop.run_until_complete(coro)
  File "/usr/lib/python3.6/asyncio/base_events.py", line 484, in run_until_complete
    return future.result()
  File "/usr/local/lib/python3.6/dist-packages/telethon/client/users.py", line 30, in __call__
    return await self._call(self._sender, request, ordered=ordered)
  File "/usr/local/lib/python3.6/dist-packages/telethon/client/users.py", line 79, in _call
    result = await future
telethon.errors.rpcerrorlist.UserIdInvalidError: Invalid object ID for a user. Make sure to pass the right types, for instance making sure that the request is designed for users or otherwise look for a different one more suited (caused by InviteToChannelRequest)
Traceback (most recent call last):
  File "./add_members_to_group.py", line 109, in <module>
    client(InviteToChannelRequest(target_group_entity,[user_to_add]))
  File "/usr/local/lib/python3.6/dist-packages/telethon/sync.py", line 39, in syncified
    return loop.run_until_complete(coro)
  File "/usr/lib/python3.6/asyncio/base_events.py", line 484, in run_until_complete
    return future.result()
  File "/usr/local/lib/python3.6/dist-packages/telethon/client/users.py", line 30, in __call__
    return await self._call(self._sender, request, ordered=ordered)
  File "/usr/local/lib/python3.6/dist-packages/telethon/client/users.py", line 79, in _call
    result = await future
telethon.errors.rpcerrorlist.UserIdInvalidError: Invalid object ID for a user. Make sure to pass the right types, for instance making sure that the request is designed for users or otherwise look for a different one more suited (caused by InviteToChannelRequest)
Traceback (most recent call last):
  File "./add_members_to_group.py", line 109, in <module>
    client(InviteToChannelRequest(target_group_entity,[user_to_add]))
  File "/usr/local/lib/python3.6/dist-packages/telethon/sync.py", line 39, in syncified
    return loop.run_until_complete(coro)
  File "/usr/lib/python3.6/asyncio/base_events.py", line 484, in run_until_complete
    return future.result()
  File "/usr/local/lib/python3.6/dist-packages/telethon/client/users.py", line 30, in __call__
    return await self._call(self._sender, request, ordered=ordered)
  File "/usr/local/lib/python3.6/dist-packages/telethon/client/users.py", line 79, in _call
    result = await future
telethon.errors.rpcerrorlist.UserIdInvalidError: Invalid object ID for a user. Make sure to pass the right types, for instance making sure that the request is designed for users or otherwise look for a different one more suited (caused by InviteToChannelRequest)
Traceback (most recent call last):
  File "./add_members_to_group.py", line 109, in <module>
    client(InviteToChannelRequest(target_group_entity,[user_to_add]))
  File "/usr/local/lib/python3.6/dist-packages/telethon/sync.py", line 39, in syncified
    return loop.run_until_complete(coro)
  File "/usr/lib/python3.6/asyncio/base_events.py", line 484, in run_until_complete
    return future.result()
  File "/usr/local/lib/python3.6/dist-packages/telethon/client/users.py", line 30, in __call__
    return await self._call(self._sender, request, ordered=ordered)
  File "/usr/local/lib/python3.6/dist-packages/telethon/client/users.py", line 79, in _call
    result = await future
telethon.errors.rpcerrorlist.UserIdInvalidError: Invalid object ID for a user. Make sure to pass the right types, for instance making sure that the request is designed for users or otherwise look for a different one more suited (caused by InviteToChannelRequest)
Traceback (most recent call last):
  File "./add_members_to_group.py", line 109, in <module>
    client(InviteToChannelRequest(target_group_entity,[user_to_add]))
  File "/usr/local/lib/python3.6/dist-packages/telethon/sync.py", line 39, in syncified
    return loop.run_until_complete(coro)
  File "/usr/lib/python3.6/asyncio/base_events.py", line 484, in run_until_complete
    return future.result()
  File "/usr/local/lib/python3.6/dist-packages/telethon/client/users.py", line 30, in __call__
    return await self._call(self._sender, request, ordered=ordered)
  File "/usr/local/lib/python3.6/dist-packages/telethon/client/users.py", line 79, in _call
    result = await future
telethon.errors.rpcerrorlist.UserIdInvalidError: Invalid object ID for a user. Make sure to pass the right types, for instance making sure that the request is designed for users or otherwise look for a different one more suited (caused by InviteToChannelRequest)
Traceback (most recent call last):
  File "./add_members_to_group.py", line 109, in <module>
    client(InviteToChannelRequest(target_group_entity,[user_to_add]))
  File "/usr/local/lib/python3.6/dist-packages/telethon/sync.py", line 39, in syncified
    return loop.run_until_complete(coro)
  File "/usr/lib/python3.6/asyncio/base_events.py", line 484, in run_until_complete
    return future.result()
  File "/usr/local/lib/python3.6/dist-packages/telethon/client/users.py", line 30, in __call__
    return await self._call(self._sender, request, ordered=ordered)
  File "/usr/local/lib/python3.6/dist-packages/telethon/client/users.py", line 79, in _call
    result = await future
telethon.errors.rpcerrorlist.UserIdInvalidError: Invalid object ID for a user. Make sure to pass the right types, for instance making sure that the request is designed for users or otherwise look for a different one more suited (caused by InviteToChannelRequest)
Traceback (most recent call last):
  File "./add_members_to_group.py", line 109, in <module>
    client(InviteToChannelRequest(target_group_entity,[user_to_add]))
  File "/usr/local/lib/python3.6/dist-packages/telethon/sync.py", line 39, in syncified
    return loop.run_until_complete(coro)
  File "/usr/lib/python3.6/asyncio/base_events.py", line 484, in run_until_complete
    return future.result()
  File "/usr/local/lib/python3.6/dist-packages/telethon/client/users.py", line 30, in __call__
    return await self._call(self._sender, request, ordered=ordered)
  File "/usr/local/lib/python3.6/dist-packages/telethon/client/users.py", line 79, in _call
    result = await future
telethon.errors.rpcerrorlist.UserIdInvalidError: Invalid object ID for a user. Make sure to pass the right types, for instance making sure that the request is designed for users or otherwise look for a different one more suited (caused by InviteToChannelRequest)
Traceback (most recent call last):
  File "./add_members_to_group.py", line 109, in <module>
    client(InviteToChannelRequest(target_group_entity,[user_to_add]))
  File "/usr/local/lib/python3.6/dist-packages/telethon/sync.py", line 39, in syncified
    return loop.run_until_complete(coro)
  File "/usr/lib/python3.6/asyncio/base_events.py", line 484, in run_until_complete
    return future.result()
  File "/usr/local/lib/python3.6/dist-packages/telethon/client/users.py", line 30, in __call__
    return await self._call(self._sender, request, ordered=ordered)
  File "/usr/local/lib/python3.6/dist-packages/telethon/client/users.py", line 79, in _call
    result = await future
telethon.errors.rpcerrorlist.UserIdInvalidError: Invalid object ID for a user. Make sure to pass the right types, for instance making sure that the request is designed for users or otherwise look for a different one more suited (caused by InviteToChannelRequest)
Traceback (most recent call last):
  File "./add_members_to_group.py", line 109, in <module>
    client(InviteToChannelRequest(target_group_entity,[user_to_add]))
  File "/usr/local/lib/python3.6/dist-packages/telethon/sync.py", line 39, in syncified
    return loop.run_until_complete(coro)
  File "/usr/lib/python3.6/asyncio/base_events.py", line 484, in run_until_complete
    return future.result()
  File "/usr/local/lib/python3.6/dist-packages/telethon/client/users.py", line 30, in __call__
    return await self._call(self._sender, request, ordered=ordered)
  File "/usr/local/lib/python3.6/dist-packages/telethon/client/users.py", line 79, in _call
    result = await future
telethon.errors.rpcerrorlist.UserIdInvalidError: Invalid object ID for a user. Make sure to pass the right types, for instance making sure that the request is designed for users or otherwise look for a different one more suited (caused by InviteToChannelRequest)
Traceback (most recent call last):
  File "./add_members_to_group.py", line 109, in <module>
    client(InviteToChannelRequest(target_group_entity,[user_to_add]))
  File "/usr/local/lib/python3.6/dist-packages/telethon/sync.py", line 39, in syncified
    return loop.run_until_complete(coro)
  File "/usr/lib/python3.6/asyncio/base_events.py", line 484, in run_until_complete
    return future.result()
  File "/usr/local/lib/python3.6/dist-packages/telethon/client/users.py", line 30, in __call__
    return await self._call(self._sender, request, ordered=ordered)
  File "/usr/local/lib/python3.6/dist-packages/telethon/client/users.py", line 79, in _call
    result = await future
telethon.errors.rpcerrorlist.UserIdInvalidError: Invalid object ID for a user. Make sure to pass the right types, for instance making sure that the request is designed for users or otherwise look for a different one more suited (caused by InviteToChannelRequest)
Traceback (most recent call last):
  File "./add_members_to_group.py", line 109, in <module>
    client(InviteToChannelRequest(target_group_entity,[user_to_add]))
  File "/usr/local/lib/python3.6/dist-packages/telethon/sync.py", line 39, in syncified
    return loop.run_until_complete(coro)
  File "/usr/lib/python3.6/asyncio/base_events.py", line 484, in run_until_complete
    return future.result()
  File "/usr/local/lib/python3.6/dist-packages/telethon/client/users.py", line 30, in __call__
    return await self._call(self._sender, request, ordered=ordered)
  File "/usr/local/lib/python3.6/dist-packages/telethon/client/users.py", line 79, in _call
    result = await future
telethon.errors.rpcerrorlist.UserIdInvalidError: Invalid object ID for a user. Make sure to pass the right types, for instance making sure that the request is designed for users or otherwise look for a different one more suited (caused by InviteToChannelRequest)
Traceback (most recent call last):
  File "./add_members_to_group.py", line 109, in <module>
    client(InviteToChannelRequest(target_group_entity,[user_to_add]))
  File "/usr/local/lib/python3.6/dist-packages/telethon/sync.py", line 39, in syncified
    return loop.run_until_complete(coro)
  File "/usr/lib/python3.6/asyncio/base_events.py", line 484, in run_until_complete
    return future.result()
  File "/usr/local/lib/python3.6/dist-packages/telethon/client/users.py", line 30, in __call__
    return await self._call(self._sender, request, ordered=ordered)
  File "/usr/local/lib/python3.6/dist-packages/telethon/client/users.py", line 79, in _call
    result = await future
telethon.errors.rpcerrorlist.UserIdInvalidError: Invalid object ID for a user. Make sure to pass the right types, for instance making sure that the request is designed for users or otherwise look for a different one more suited (caused by InviteToChannelRequest)
Traceback (most recent call last):
  File "./add_members_to_group.py", line 109, in <module>
    client(InviteToChannelRequest(target_group_entity,[user_to_add]))
  File "/usr/local/lib/python3.6/dist-packages/telethon/sync.py", line 39, in syncified
    return loop.run_until_complete(coro)
  File "/usr/lib/python3.6/asyncio/base_events.py", line 484, in run_until_complete
    return future.result()
  File "/usr/local/lib/python3.6/dist-packages/telethon/client/users.py", line 30, in __call__
    return await self._call(self._sender, request, ordered=ordered)
  File "/usr/local/lib/python3.6/dist-packages/telethon/client/users.py", line 79, in _call
    result = await future
telethon.errors.rpcerrorlist.UserIdInvalidError: Invalid object ID for a user. Make sure to pass the right types, for instance making sure that the request is designed for users or otherwise look for a different one more suited (caused by InviteToChannelRequest)
Traceback (most recent call last):
  File "./add_members_to_group.py", line 109, in <module>
    client(InviteToChannelRequest(target_group_entity,[user_to_add]))
  File "/usr/local/lib/python3.6/dist-packages/telethon/sync.py", line 39, in syncified
    return loop.run_until_complete(coro)
  File "/usr/lib/python3.6/asyncio/base_events.py", line 484, in run_until_complete
    return future.result()
  File "/usr/local/lib/python3.6/dist-packages/telethon/client/users.py", line 30, in __call__
    return await self._call(self._sender, request, ordered=ordered)
  File "/usr/local/lib/python3.6/dist-packages/telethon/client/users.py", line 79, in _call
    result = await future
telethon.errors.rpcerrorlist.UserIdInvalidError: Invalid object ID for a user. Make sure to pass the right types, for instance making sure that the request is designed for users or otherwise look for a different one more suited (caused by InviteToChannelRequest)
Traceback (most recent call last):
  File "./add_members_to_group.py", line 109, in <module>
    client(InviteToChannelRequest(target_group_entity,[user_to_add]))
  File "/usr/local/lib/python3.6/dist-packages/telethon/sync.py", line 39, in syncified
    return loop.run_until_complete(coro)
  File "/usr/lib/python3.6/asyncio/base_events.py", line 484, in run_until_complete
    return future.result()
  File "/usr/local/lib/python3.6/dist-packages/telethon/client/users.py", line 30, in __call__
    return await self._call(self._sender, request, ordered=ordered)
  File "/usr/local/lib/python3.6/dist-packages/telethon/client/users.py", line 79, in _call
    result = await future
telethon.errors.rpcerrorlist.UserIdInvalidError: Invalid object ID for a user. Make sure to pass the right types, for instance making sure that the request is designed for users or otherwise look for a different one more suited (caused by InviteToChannelRequest)
Traceback (most recent call last):
  File "./add_members_to_group.py", line 109, in <module>
    client(InviteToChannelRequest(target_group_entity,[user_to_add]))
  File "/usr/local/lib/python3.6/dist-packages/telethon/sync.py", line 39, in syncified
    return loop.run_until_complete(coro)
  File "/usr/lib/python3.6/asyncio/base_events.py", line 484, in run_until_complete
    return future.result()
  File "/usr/local/lib/python3.6/dist-packages/telethon/client/users.py", line 30, in __call__
    return await self._call(self._sender, request, ordered=ordered)
  File "/usr/local/lib/python3.6/dist-packages/telethon/client/users.py", line 79, in _call
    result = await future
telethon.errors.rpcerrorlist.UserIdInvalidError: Invalid object ID for a user. Make sure to pass the right types, for instance making sure that the request is designed for users or otherwise look for a different one more suited (caused by InviteToChannelRequest)
Traceback (most recent call last):
  File "./add_members_to_group.py", line 109, in <module>
    client(InviteToChannelRequest(target_group_entity,[user_to_add]))
  File "/usr/local/lib/python3.6/dist-packages/telethon/sync.py", line 39, in syncified
    return loop.run_until_complete(coro)
  File "/usr/lib/python3.6/asyncio/base_events.py", line 484, in run_until_complete
    return future.result()
  File "/usr/local/lib/python3.6/dist-packages/telethon/client/users.py", line 30, in __call__
    return await self._call(self._sender, request, ordered=ordered)
  File "/usr/local/lib/python3.6/dist-packages/telethon/client/users.py", line 79, in _call
    result = await future
telethon.errors.rpcerrorlist.UserIdInvalidError: Invalid object ID for a user. Make sure to pass the right types, for instance making sure that the request is designed for users or otherwise look for a different one more suited (caused by InviteToChannelRequest)
Traceback (most recent call last):
  File "./add_members_to_group.py", line 109, in <module>
    client(InviteToChannelRequest(target_group_entity,[user_to_add]))
  File "/usr/local/lib/python3.6/dist-packages/telethon/sync.py", line 39, in syncified
    return loop.run_until_complete(coro)
  File "/usr/lib/python3.6/asyncio/base_events.py", line 484, in run_until_complete
    return future.result()
  File "/usr/local/lib/python3.6/dist-packages/telethon/client/users.py", line 30, in __call__
    return await self._call(self._sender, request, ordered=ordered)
  File "/usr/local/lib/python3.6/dist-packages/telethon/client/users.py", line 79, in _call
    result = await future
telethon.errors.rpcerrorlist.UserIdInvalidError: Invalid object ID for a user. Make sure to pass the right types, for instance making sure that the request is designed for users or otherwise look for a different one more suited (caused by InviteToChannelRequest)
Traceback (most recent call last):
  File "./add_members_to_group.py", line 109, in <module>
    client(InviteToChannelRequest(target_group_entity,[user_to_add]))
  File "/usr/local/lib/python3.6/dist-packages/telethon/sync.py", line 39, in syncified
    return loop.run_until_complete(coro)
  File "/usr/lib/python3.6/asyncio/base_events.py", line 484, in run_until_complete
    return future.result()
  File "/usr/local/lib/python3.6/dist-packages/telethon/client/users.py", line 30, in __call__
    return await self._call(self._sender, request, ordered=ordered)
  File "/usr/local/lib/python3.6/dist-packages/telethon/client/users.py", line 79, in _call
    result = await future
telethon.errors.rpcerrorlist.UserIdInvalidError: Invalid object ID for a user. Make sure to pass the right types, for instance making sure that the request is designed for users or otherwise look for a different one more suited (caused by InviteToChannelRequest)
Traceback (most recent call last):
  File "./add_members_to_group.py", line 109, in <module>
    client(InviteToChannelRequest(target_group_entity,[user_to_add]))
  File "/usr/local/lib/python3.6/dist-packages/telethon/sync.py", line 39, in syncified
    return loop.run_until_complete(coro)
  File "/usr/lib/python3.6/asyncio/base_events.py", line 484, in run_until_complete
    return future.result()
  File "/usr/local/lib/python3.6/dist-packages/telethon/client/users.py", line 30, in __call__
    return await self._call(self._sender, request, ordered=ordered)
  File "/usr/local/lib/python3.6/dist-packages/telethon/client/users.py", line 79, in _call
    result = await future
telethon.errors.rpcerrorlist.UserIdInvalidError: Invalid object ID for a user. Make sure to pass the right types, for instance making sure that the request is designed for users or otherwise look for a different one more suited (caused by InviteToChannelRequest)
Traceback (most recent call last):
  File "./add_members_to_group.py", line 109, in <module>
    client(InviteToChannelRequest(target_group_entity,[user_to_add]))
  File "/usr/local/lib/python3.6/dist-packages/telethon/sync.py", line 39, in syncified
    return loop.run_until_complete(coro)
  File "/usr/lib/python3.6/asyncio/base_events.py", line 484, in run_until_complete
    return future.result()
  File "/usr/local/lib/python3.6/dist-packages/telethon/client/users.py", line 30, in __call__
    return await self._call(self._sender, request, ordered=ordered)
  File "/usr/local/lib/python3.6/dist-packages/telethon/client/users.py", line 79, in _call
    result = await future
telethon.errors.rpcerrorlist.UserIdInvalidError: Invalid object ID for a user. Make sure to pass the right types, for instance making sure that the request is designed for users or otherwise look for a different one more suited (caused by InviteToChannelRequest)
Traceback (most recent call last):
  File "./add_members_to_group.py", line 109, in <module>
    client(InviteToChannelRequest(target_group_entity,[user_to_add]))
  File "/usr/local/lib/python3.6/dist-packages/telethon/sync.py", line 39, in syncified
    return loop.run_until_complete(coro)
  File "/usr/lib/python3.6/asyncio/base_events.py", line 484, in run_until_complete
    return future.result()
  File "/usr/local/lib/python3.6/dist-packages/telethon/client/users.py", line 30, in __call__
    return await self._call(self._sender, request, ordered=ordered)
  File "/usr/local/lib/python3.6/dist-packages/telethon/client/users.py", line 79, in _call
    result = await future
telethon.errors.rpcerrorlist.UserIdInvalidError: Invalid object ID for a user. Make sure to pass the right types, for instance making sure that the request is designed for users or otherwise look for a different one more suited (caused by InviteToChannelRequest)
Traceback (most recent call last):
  File "./add_members_to_group.py", line 109, in <module>
    client(InviteToChannelRequest(target_group_entity,[user_to_add]))
  File "/usr/local/lib/python3.6/dist-packages/telethon/sync.py", line 39, in syncified
    return loop.run_until_complete(coro)
  File "/usr/lib/python3.6/asyncio/base_events.py", line 484, in run_until_complete
    return future.result()
  File "/usr/local/lib/python3.6/dist-packages/telethon/client/users.py", line 30, in __call__
    return await self._call(self._sender, request, ordered=ordered)
  File "/usr/local/lib/python3.6/dist-packages/telethon/client/users.py", line 79, in _call
    result = await future
telethon.errors.rpcerrorlist.UserIdInvalidError: Invalid object ID for a user. Make sure to pass the right types, for instance making sure that the request is designed for users or otherwise look for a different one more suited (caused by InviteToChannelRequest)
Traceback (most recent call last):
  File "./add_members_to_group.py", line 109, in <module>
    client(InviteToChannelRequest(target_group_entity,[user_to_add]))
  File "/usr/local/lib/python3.6/dist-packages/telethon/sync.py", line 39, in syncified
    return loop.run_until_complete(coro)
  File "/usr/lib/python3.6/asyncio/base_events.py", line 484, in run_until_complete
    return future.result()
  File "/usr/local/lib/python3.6/dist-packages/telethon/client/users.py", line 30, in __call__
    return await self._call(self._sender, request, ordered=ordered)
  File "/usr/local/lib/python3.6/dist-packages/telethon/client/users.py", line 79, in _call
    result = await future
telethon.errors.rpcerrorlist.UserIdInvalidError: Invalid object ID for a user. Make sure to pass the right types, for instance making sure that the request is designed for users or otherwise look for a different one more suited (caused by InviteToChannelRequest)
Ethio_Online_Market
#1 Market
GDG Addis: Discussion Group
GDG Addis
BeU - SALES-TEAM-4
BeU - SALES-TEAM-4
ዘመነ ማርኬት
Zemene market
🔥🔥 😲😲PROMOTIONS AND DISCOUNTS!!!👏 👏 👀
World of Fashion
Maki gifts
Maki gifts
qnash.com - ቅናሽ
ሱቄን በእጄ MARKET💸💯🔑
Testing
Hh
Emerald
GDG Addis
Maki gifts 🎁🎁🎁🎁
Adding 1368838274, 
Unexpected Error
Adding 933408533, 
Unexpected Error
Adding 341983095, 
Unexpected Error
Adding 631251415, 
Unexpected Error
Adding 1885823118, 
Unexpected Error
Adding 1866563311, 
Unexpected Error
Adding 1861045663, 
Unexpected Error
Adding 1580072185, 
Unexpected Error
Adding 853123857, 
Unexpected Error
Adding 769914274, Zeki7
Waiting for 60-180 Seconds...
Adding 481542170, 
Unexpected Error
Adding 416440569, zoomhope
Waiting for 60-180 Seconds...
Adding 499289038, ZAbukiya
Waiting for 60-180 Seconds...
Adding 375749671, ZAH_DESIGNS
Waiting for 60-180 Seconds...
Adding 346217753, ab_z_tu2
Waiting for 60-180 Seconds...
Adding 406721062, 
Unexpected Error
Adding 336333013, 
Unexpected Error
Adding 592408399, Zeamanuelawin
Waiting for 60-180 Seconds...
Adding 1476365724, 
Unexpected Error
Adding 637588312, nettty
Waiting for 60-180 Seconds...
Adding 394398652, tarzol12
The user's privacy settings do not allow you to do this. Skipping.
Adding 452863112, zam24012436
Waiting for 60-180 Seconds...
Adding 979523393, Maafffiii
Waiting for 60-180 Seconds...
Adding 595745413, Zel12
Waiting for 60-180 Seconds...
Adding 1247397774, Hopepanda
Waiting for 60-180 Seconds...
Adding 850928802, 
Unexpected Error
Adding 360836621, Zeydbereket
The user's privacy settings do not allow you to do this. Skipping.
Adding 459433426, Jordi4j_42
Waiting for 60-180 Seconds...
Adding 1155755128, zetemuchalian
Waiting for 60-180 Seconds...
Adding 364847644, Ab_zizooo
Waiting for 60-180 Seconds...
Adding 537669246, Betremariyamm
Waiting for 60-180 Seconds...
Adding 753026947, 
Unexpected Error
Adding 377700982, 
Unexpected Error
Adding 965013070, beza03
Waiting for 60-180 Seconds...
Adding 913623043, 
Unexpected Error
Adding 447030604, HGIEWDOITON
Waiting for 60-180 Seconds...
Adding 430426215, 
Unexpected Error
Adding 338065281, Zeyadu
Waiting for 60-180 Seconds...
Adding 1615274365, 
Unexpected Error
Adding 706542057, Gibson264
The user's privacy settings do not allow you to do this. Skipping.
Adding 1224792045, 
Unexpected Error
Adding 365003421, Zmichot
Waiting for 60-180 Seconds...
Adding 749230431, Aalih_hbibi_wadhlh
Waiting for 60-180 Seconds...
Adding 634289087, 
Unexpected Error
Adding 931095724, 
Unexpected Error
Adding 506899391, 
Unexpected Error
Adding 1415757127, 
Unexpected Error
Adding 357484933, zekarias7
The user's privacy settings do not allow you to do this. Skipping.
Adding 1539585601, Zureem
Waiting for 60-180 Seconds...
